2022-04-03 21:57:38,694 INFO    MainThread:9144 [internal.py:wandb_internal():87] W&B internal server running at pid: 9144, started at: 2022-04-03 21:57:38.694173
2022-04-03 21:57:38,696 INFO    WriterThread:9144 [datastore.py:open_for_write():77] open: C:\Users\mahdi\Desktop\Github_Work\1\RSNA-Bone-Age\wandb\run-20220403_215735-hmugma1u\run-hmugma1u.wandb
2022-04-03 21:57:38,697 DEBUG   HandlerThread:9144 [handler.py:handle_request():130] handle_request: check_version
2022-04-03 21:57:38,700 DEBUG   SenderThread:9144 [sender.py:send():234] send: header
2022-04-03 21:57:38,700 DEBUG   SenderThread:9144 [sender.py:send_request():248] send_request: check_version
2022-04-03 21:57:39,517 DEBUG   SenderThread:9144 [sender.py:send():234] send: run
2022-04-03 21:57:39,923 ERROR   SenderThread:9144 [internal_api.py:execute():144] 403 response executing GraphQL.
2022-04-03 21:57:39,923 ERROR   SenderThread:9144 [internal_api.py:execute():145] 
<html><head>
<meta http-equiv="content-type" content="text/html;charset=utf-8">
<title>403 Forbidden</title>
</head>
<body text=#000000 bgcolor=#ffffff>
<h1>Error: Forbidden</h1>
<h2>Your client does not have permission to get URL <code>/graphql</code> from this server.</h2>
<h2></h2>
</body></html>

2022-04-03 21:57:40,528 INFO    WriterThread:9144 [datastore.py:close():281] close: C:\Users\mahdi\Desktop\Github_Work\1\RSNA-Bone-Age\wandb\run-20220403_215735-hmugma1u\run-hmugma1u.wandb
2022-04-03 21:57:40,528 INFO    HandlerThread:9144 [handler.py:finish():731] shutting down handler
2022-04-03 21:57:40,715 ERROR   MainThread:9144 [internal.py:wandb_internal():158] Thread SenderThread:
Traceback (most recent call last):
  File "C:\Python\Python39\lib\site-packages\wandb\sdk\lib\retry.py", line 102, in __call__
    result = self._call_fn(*args, **kwargs)
  File "C:\Python\Python39\lib\site-packages\wandb\sdk\internal\internal_api.py", line 147, in execute
    six.reraise(*sys.exc_info())
  File "C:\Users\mahdi\AppData\Roaming\Python\Python39\site-packages\six.py", line 719, in reraise
    raise value
  File "C:\Python\Python39\lib\site-packages\wandb\sdk\internal\internal_api.py", line 141, in execute
    return self.client.execute(*args, **kwargs)
  File "C:\Python\Python39\lib\site-packages\wandb\vendor\gql-0.2.0\gql\client.py", line 52, in execute
    result = self._get_result(document, *args, **kwargs)
  File "C:\Python\Python39\lib\site-packages\wandb\vendor\gql-0.2.0\gql\client.py", line 60, in _get_result
    return self.transport.execute(document, *args, **kwargs)
  File "C:\Python\Python39\lib\site-packages\wandb\vendor\gql-0.2.0\gql\transport\requests.py", line 39, in execute
    request.raise_for_status()
  File "C:\Python\Python39\lib\site-packages\requests\models.py", line 960, in raise_for_status
    raise HTTPError(http_error_msg, response=self)
requests.exceptions.HTTPError: 403 Client Error: Forbidden for url: https://api.wandb.ai/graphql

During handling of the above exception, another exception occurred:

Traceback (most recent call last):
  File "C:\Python\Python39\lib\site-packages\wandb\apis\normalize.py", line 24, in wrapper
    return func(*args, **kwargs)
  File "C:\Python\Python39\lib\site-packages\wandb\sdk\internal\internal_api.py", line 1298, in upsert_run
    response = self.gql(mutation, variable_values=variable_values, **kwargs)
  File "C:\Python\Python39\lib\site-packages\wandb\sdk\lib\retry.py", line 118, in __call__
    if not check_retry_fn(e):
  File "C:\Python\Python39\lib\site-packages\wandb\util.py", line 821, in no_retry_auth
    raise CommError("Permission denied, ask the project owner to grant you access")
wandb.errors.CommError: Permission denied, ask the project owner to grant you access

During handling of the above exception, another exception occurred:

Traceback (most recent call last):
  File "C:\Python\Python39\lib\site-packages\wandb\sdk\internal\internal_util.py", line 52, in run
    self._run()
  File "C:\Python\Python39\lib\site-packages\wandb\sdk\internal\internal_util.py", line 102, in _run
    self._process(record)
  File "C:\Python\Python39\lib\site-packages\wandb\sdk\internal\internal.py", line 291, in _process
    self._sm.send(record)
  File "C:\Python\Python39\lib\site-packages\wandb\sdk\internal\sender.py", line 236, in send
    send_handler(record)
  File "C:\Python\Python39\lib\site-packages\wandb\sdk\internal\sender.py", line 687, in send_run
    self._init_run(run, config_value_dict)
  File "C:\Python\Python39\lib\site-packages\wandb\sdk\internal\sender.py", line 711, in _init_run
    server_run, inserted = self._api.upsert_run(
  File "C:\Python\Python39\lib\site-packages\wandb\apis\normalize.py", line 62, in wrapper
    six.reraise(CommError, CommError(message, err), sys.exc_info()[2])
  File "C:\Users\mahdi\AppData\Roaming\Python\Python39\site-packages\six.py", line 718, in reraise
    raise value.with_traceback(tb)
  File "C:\Python\Python39\lib\site-packages\wandb\apis\normalize.py", line 24, in wrapper
    return func(*args, **kwargs)
  File "C:\Python\Python39\lib\site-packages\wandb\sdk\internal\internal_api.py", line 1298, in upsert_run
    response = self.gql(mutation, variable_values=variable_values, **kwargs)
  File "C:\Python\Python39\lib\site-packages\wandb\sdk\lib\retry.py", line 118, in __call__
    if not check_retry_fn(e):
  File "C:\Python\Python39\lib\site-packages\wandb\util.py", line 821, in no_retry_auth
    raise CommError("Permission denied, ask the project owner to grant you access")
wandb.errors.CommError: Permission denied, ask the project owner to grant you access
2022-04-03 21:57:42,838 INFO    MainThread:9144 [internal.py:handle_exit():77] Internal process exited
